<mujoco model="dual-panda v01">

    <include file="panda/assets/basic_scene.xml" />
    <include file="panda/assets/assets.xml" />
    <include file="panda/assets/gripper_assets.xml" />
    <include file="panda/assets/sensors.xml" />

    <!-- change this for different objects -->

    <!-- <include file="include.xml"/> -->
    <!-- <include file="panda/assets/table.xml" /> -->
    <!-- <include file="panda/assets/monitor.xml"/> -->

    <compiler meshdir="" />
    <option noslip_iterations="20"> </option>
    <!-- <option condim="6"> </option> -->
    <option cone="elliptic"> </option>
    <option><flag multiccd="enable"/> </option>

    <default>
        <default class='torso'>
            <geom group='2' contype='0' conaffinity='0' rgba=".95 .99 .92 1" />
        </default>/ </default>

    <worldbody>

        <body name='torso' childclass='torso'>
            <!-- <geom name='shoulders' type='capsule' size='.075' fromto='.15 0 .9 -.15 0 .9' />
            <geom name='absL' type='capsule' size='.06' fromto='.15 0 .9 0.05 0 .35' />
            <geom name='absR' type='capsule' size='.06' fromto='-.15 0 .9 -.05 0 .35' />
            <geom name='legs' type='capsule' size='.115' fromto='0 0 .35 0 0 0.05' /> -->

            <body name='leftarm' pos='0 -0.25 0' euler='0 0 3.14'>
                <include file="panda/assets/chainL.xml" />
            </body>

            <body name='rightarm' pos='0 0.25 0' euler='0 0 3.14'>
                <include file="panda/assets/chainR.xml" />
            </body>

        </body>

        <body name="chassis" pos="0 0 0.2" euler='0 90 0'>
            <inertial pos="0 0 0" mass="10" diaginertia="0 0 0" />
			<joint type="free"/>
			<geom type="box" size=".03 .2 .4" rgba=".9 .9 0 1"/>
			<body name="left-tire" pos="0 0.25 -0.4" euler='90 0 0'>
				<joint name="left-wheel" type="hinge" axis="0 0 -1" damping="0.001"/>
				<geom type="cylinder" size="0.1 0.03" rgba="0 .9 0 1" friction="0.5 0.1 0.1"/>
			</body>
			<body name="right-tire" pos="0 -0.25 -0.4" euler='90 0 0'>
				<joint name="right-wheel" type="hinge" axis="0 0 -1" damping="0.001"/>
				<geom type="cylinder" size="0.1 0.03" rgba="0 .9 0 1" friction="0.5 0.1 0.1"/>
			</body>
			<body name="front-left-tire" pos="0 0.25 0.4" euler='90 0 0'>
				<joint name="front-left-wheel" type="hinge" axis="0 0 -1" damping="0.001"/>
				<geom type="cylinder" size="0.1 0.03" rgba="0 .9 0 1" friction="0.5 0.1 0.1"/>
			</body>
			<body name="front-right-tire" pos="0 -0.25 0.4" euler='90 0 0'>
				<joint name="front-right-wheel" type="hinge" axis="0 0 -1" damping="0.001"/>
				<geom type="cylinder" size="0.1 0.03" rgba="0 .9 0 1" friction="0.5 0.1 0.1"/>
			</body>
			<body name="handle1" pos="-0.2 0.1 0.35" euler='0 0 0'>
				<geom type="box" size=".2 .02 .02" rgba=".5 .5 .5 1"/>
			</body>
            <body name="handle2" pos="-0.2 -0.1 0.35" euler='0 0 0'>
				<geom type="box" size=".2 .02 .02" rgba=".5 .5 .5 1"/>
                <body name="handle3" pos="-0.2 0.1 0" euler='0 0 0'>
                    <geom type="box" size=".02 .2 .02" rgba=".5 .5 .5 1"/>
                </body>
			</body>
		</body>



    </worldbody>

    <include file='panda/assets/actuatorL.xml' />
    <include file='panda/assets/gripper_actuatorL.xml' />
    <include file='panda/assets/actuatorR.xml' />
    <include file='panda/assets/gripper_actuatorR.xml' />

</mujoco>
    