<mujoco model="dual-panda v01">
    <include file="panda/assets/assets.xml" />
    <asset>
        <texture name="texplane" type="2d" builtin="checker" rgb1=".2 .3 .4" rgb2=".1 0.15 0.2"
                width="512" height="512"/>
        <material name="MatGnd" reflectance="0.5" texture="texplane" texrepeat="1 1" texuniform="true"/>
    </asset>
    <!-- change this for different objects -->

    <!-- <include file="include.xml"/> -->
    <include file="panda/assets/tray.xml" />
    <!-- <include file="panda/assets/monitor.xml"/> -->

<compiler meshdir="" />

    <option noslip_iterations="50" />
    <option solver="Newton" iterations="100" tolerance="1e-5"/>

    <!-- <option noslip_iterations="20"> </option> -->
    <!-- <option solimp="0.9 0.95 0.001"> </option> -->
    <!-- <option condim="6"> </option> -->
    <option cone="elliptic"> </option>
    <option><flag multiccd="enable"/> </option>
    <worldbody>
        <light directional="false" diffuse=".8 .8 .8" specular="0.3 0.3 0.3" pos="1  1 3" dir="-1 -1 -3"/>
        <light directional="false" diffuse=".8 .8 .8" specular="0.3 0.3 0.3" pos="1 -1 3" dir="-1 1 -3"/>
        <light directional="false" diffuse=".8 .8 .8" specular="0.3 0.3 0.3" pos="-1 0 3" dir="1 0 -3" />
        <geom name="ground" pos="0 0 0" size="5 5 10" material="MatGnd" type="plane" contype="1" conaffinity="1"/>

        <!-- <include file="object.xml"/> -->
            <!-- 0 0.3 0.2 -->
        <body name="collision_object" pos="0.0 0 0.3" quat="1 0 0 0">
            <joint type="hinge" name="object_virtual_joint" pos="0.0 0.0 0.0" axis="1 0 0" damping="1" />
            <joint type="hinge" name="object_virtual_joint_y" pos="0.0 0.0 0.0" axis="0 1 0" damping="1" />
            <!-- <geom class="object_viz" mesh="tray_viz"  rgba = "0.52941176 0.24313725 0.1372549 1"/>
            <geom class="object_col" mesh="trayPart-0" friction="0.1 100.0 500.0"/>
            <geom class="object_col" mesh="trayPart-1" friction="100.0 500 500.0"/>
            <geom class="object_col" mesh="trayPart-2" friction="100.0 500 500.0"/> -->
            <geom type="box" size="0.5 0.5 0.01" rgba="0 0 1 1 " friction="0.1 0.1 0.1"  condim="6" />
            <inertial pos="0 0 0" mass="2" diaginertia="0.03013 0.08413 0.11333" />
        </body>

        <!-- <body name="box_body" pos="-0.36 -0.5 0.3" quat="1 0 0 0">
            <joint type="free" damping="10"/>
            <geom type="box" size="0.04 0.04 0.08" rgba="1 0 0 1" friction="0.8 0.1 0.05"/>
            <inertial pos="0 0 0" mass="1" diaginertia="2 2 2" />
        </body> -->
        <!-- -0.36 0.5 0.3 -->
        <body name="cylinder_body" pos=".2 0.3 0.35" quat="0 0.7071068 0 0.7071068">
            
            <joint type="free" />
            <!-- <joint type="free" name="object_virtual_joint_10" pos="0.0 0.0 0.0" damping="20"/> -->

            <geom type="sphere" size="0.04 0.04 0.04" rgba="1 1 0 1" friction="0.1 0.1 0.1"  condim="6"/>
            <inertial pos="0 0 0" mass="1" diaginertia="0.024 0.024 0.0136"/>
        </body>
        <!-- <body name="box_body1" pos="-0.0 0.0 0.08" quat="1 0 0 0"> -->
            <!-- <joint type="free" /> -->
            <!-- <geom type="box" size="0.16 0.16 0.18" rgba="0 0 1 1" /> -->
            <!-- <inertial pos="0 0 0" mass="2" diaginertia="2 2 2" /> -->
        <!-- </body> -->

    </worldbody>

    <actuator>
        <position ctrllimited="true" ctrlrange="-2 2" joint="object_virtual_joint" kp="10"/>
        <position ctrllimited="true" ctrlrange="-2 2" joint="object_virtual_joint_y" kp="10"/>
    </actuator>
</mujoco>
